<?xml version="1.0" ?>
<robot name="ur5" xmlns:xacro="http://ros.org/wiki/xacro">
  <link name="base_link">
  </link>

  <link name="cuboid">
    <visual>
      <geometry>
        <box size="0.6 0.6 0.2"/>
      </geometry>
      <material name="LightGrey">
        <color rgba="0.7 0.7 0.7 1.0"/>
      </material>
    </visual>
    <collision>
      <geometry>
        <box size="0.6 0.6 0.2"/>
      </geometry>
    </collision>
  </link>

  <joint name="cuboid_joint" type="floating">
    <parent link="base_link"/>
    <child link="cuboid"/>
    <limit effort="150.0" velocity="3.15"/>
  </joint>
</robot>
