<?xml version="1.0" ?>
<!-- =================================================================================== -->
<!-- |    This document was autogenerated by xacro from ur_description/urdf/ur10e.xacro | -->
<!-- |    EDITING THIS FILE BY HAND IS NOT RECOMMENDED                                 | -->
<!-- =================================================================================== -->
<robot name="dual_ur5_robot">

  <!--################################################
  ########            shared base              #######
  ####################################################-->

  <link name="base_fixture_link"/>

  <!--################################################
  ########              arm 0                  #######
  ####################################################-->

  <link name="base_link_0">
    <visual>
      <geometry>
        <mesh filename="../ur5/meshes/visual/base.obj"/>
      </geometry>
      <material name="LightGrey">
        <color rgba="0.7 0.7 0.7 1.0"/>
      </material>
    </visual>
    <collision>
      <geometry>
        <mesh filename="../ur5/meshes/collision/base.stl"/>
      </geometry>
    </collision>
    <inertial>
      <mass value="4.0"/>
      <origin rpy="0 0 0" xyz="0.0 0.0 0.0"/>
      <inertia ixx="0.00443333156" ixy="0.0" ixz="0.0" iyy="0.00443333156" iyz="0.0" izz="0.0072"/>
    </inertial>
  </link>

  <joint name="shoulder_pan_joint_0" type="revolute">
    <parent link="base_link_0"/>
    <child link="shoulder_link_0"/>
    <origin rpy="0.0 0.0 0.0" xyz="0.0 0.0 0.089159"/>
    <axis xyz="0 0 1"/>
    <limit effort="150.0" lower="-3.14159265359" upper="3.14159265359" velocity="3.15"/>
    <dynamics damping="0.1" friction="0.0"/>
  </joint>
  <link name="shoulder_link_0">
    <visual>
      <geometry>
        <mesh filename="../ur5/meshes/visual/shoulder.obj"/>
      </geometry>
      <material name="UR-Blue">
        <color rgba="0.376 0.576 0.674 1.0"/>
      </material>
    </visual>
    <collision>
      <geometry>
        <mesh filename="../ur5/meshes/collision/shoulder.stl"/>
      </geometry>
    </collision>
    <inertial>
      <mass value="3.7"/>
      <origin rpy="0 0 0" xyz="0.0 0.0 0.0"/>
      <inertia ixx="0.010267495893" ixy="0.0" ixz="0.0" iyy="0.010267495893" iyz="0.0" izz="0.00666"/>
    </inertial>
  </link>
  <joint name="shoulder_lift_joint_0" type="revolute">
    <parent link="shoulder_link_0"/>
    <child link="upper_arm_link_0"/>
    <origin rpy="0.0 1.57079632679 0.0" xyz="0.0 0.13585 0.0"/>
    <axis xyz="0 1 0"/>
    <limit effort="150.0" lower="-3.14159265359" upper="3.14159265359" velocity="3.15"/>
    <dynamics damping="0.1" friction="0.0"/>
  </joint>
  <link name="upper_arm_link_0">
    <visual>
      <geometry>
        <mesh filename="../ur5/meshes/visual/upperarm.obj"/>
      </geometry>
      <material name="LightGrey">
        <color rgba="0.7 0.7 0.7 1.0"/>
      </material>
    </visual>
    <collision>
      <geometry>
        <mesh filename="../ur5/meshes/collision/upperarm.stl"/>
      </geometry>
    </collision>
    <inertial>
      <mass value="8.393"/>
      <origin rpy="0 0 0" xyz="0.0 0.0 0.28"/>
      <inertia ixx="0.22689067591" ixy="0.0" ixz="0.0" iyy="0.22689067591" iyz="0.0" izz="0.0151074"/>
    </inertial>
  </link>
  <joint name="elbow_joint_0" type="revolute">
    <parent link="upper_arm_link_0"/>
    <child link="forearm_link_0"/>
    <origin rpy="0.0 0.0 0.0" xyz="0.0 -0.1197 0.425"/>
    <axis xyz="0 1 0"/>
    <limit effort="150.0" lower="-3.14159265359" upper="3.14159265359" velocity="3.15"/>
    <dynamics damping="0.1" friction="0.0"/>
  </joint>
  <link name="forearm_link_0">
    <visual>
      <geometry>
        <mesh filename="../ur5/meshes/visual/forearm.obj"/>
      </geometry>
      <material name="LightGrey">
        <color rgba="0.7 0.7 0.7 1.0"/>
      </material>
    </visual>
    <collision>
      <geometry>
        <mesh filename="../ur5/meshes/collision/forearm.stl"/>
      </geometry>
    </collision>
    <inertial>
      <mass value="2.275"/>
      <origin rpy="0 0 0" xyz="0.0 0.0 0.25"/>
      <inertia ixx="0.049443313556" ixy="0.0" ixz="0.0" iyy="0.049443313556" iyz="0.0" izz="0.004095"/>
    </inertial>
  </link>
  <joint name="wrist_1_joint_0" type="revolute">
    <parent link="forearm_link_0"/>
    <child link="wrist_1_link_0"/>
    <origin rpy="0.0 1.57079632679 0.0" xyz="0.0 0.0 0.39225"/>
    <axis xyz="0 1 0"/>
    <limit effort="28.0" lower="-3.14159265359" upper="3.14159265359" velocity="3.2"/>
    <dynamics damping="0.1" friction="0.0"/>
  </joint>
  <link name="wrist_1_link_0">
    <visual>
      <geometry>
        <mesh filename="../ur5/meshes/visual/wrist1.obj"/>
      </geometry>
      <material name="UR-Blue">
        <color rgba="0.376 0.576 0.674 1.0"/>
      </material>
    </visual>
    <collision>
      <geometry>
        <mesh filename="../ur5/meshes/collision/wrist1.stl"/>
      </geometry>
    </collision>
    <inertial>
      <mass value="1.219"/>
      <origin rpy="0 0 0" xyz="0.0 0.0 0.0"/>
      <inertia ixx="0.111172755531" ixy="0.0" ixz="0.0" iyy="0.111172755531" iyz="0.0" izz="0.21942"/>
    </inertial>
  </link>
  <joint name="wrist_2_joint_0" type="revolute">
    <parent link="wrist_1_link_0"/>
    <child link="wrist_2_link_0"/>
    <origin rpy="0.0 0.0 0.0" xyz="0.0 0.093 0.0"/>
    <axis xyz="0 0 1"/>
    <limit effort="28.0" lower="-3.14159265359" upper="3.14159265359" velocity="3.2"/>
    <dynamics damping="0.1" friction="0.0"/>
  </joint>
  <link name="wrist_2_link_0">
    <visual>
      <geometry>
        <mesh filename="../ur5/meshes/visual/wrist2.obj"/>
      </geometry>
      <material name="DarkGray">
        <color rgba="0.5 0.5 0.5 1.0"/>
      </material>
    </visual>
    <collision>
      <geometry>
        <mesh filename="../ur5/meshes/collision/wrist2.stl"/>
      </geometry>
    </collision>
    <inertial>
      <mass value="1.219"/>
      <origin rpy="0 0 0" xyz="0.0 0.0 0.0"/>
      <inertia ixx="0.111172755531" ixy="0.0" ixz="0.0" iyy="0.111172755531" iyz="0.0" izz="0.21942"/>
    </inertial>
  </link>
  <joint name="wrist_3_joint_0" type="revolute">
    <parent link="wrist_2_link_0"/>
    <child link="wrist_3_link_0"/>
    <origin rpy="0.0 0.0 0.0" xyz="0.0 0.0 0.09465"/>
    <axis xyz="0 1 0"/>
    <limit effort="28.0" lower="-3.14159265359" upper="3.14159265359" velocity="3.2"/>
    <dynamics damping="0.1" friction="0.0"/>
  </joint>
  <link name="wrist_3_link_0">
    <visual>
      <geometry>
        <mesh filename="../ur5/meshes/visual/wrist3.obj"/>
      </geometry>
      <material name="LightGrey">
        <color rgba="0.7 0.7 0.7 1.0"/>
      </material>
    </visual>
    <collision>
      <geometry>
        <mesh filename="../ur5/meshes/collision/wrist3.stl"/>
      </geometry>
    </collision>
    <inertial>
      <mass value="0.1879"/>
      <origin rpy="0 0 0" xyz="0.0 0.0 0.0"/>
      <inertia ixx="0.0171364731454" ixy="0.0" ixz="0.0" iyy="0.0171364731454" iyz="0.0" izz="0.033822"/>
    </inertial>
  </link>
  <joint name="ee_fixed_joint_0" type="fixed">
    <parent link="wrist_3_link_0"/>
    <child link="ee_link_0"/>
    <origin rpy="0.0 0.0 1.57079632679" xyz="0.0 0.0823 0.0"/>
    <dynamics damping="0.1" friction="0.0"/>
  </joint>
  <link name="ee_link_0">
    <collision>
      <geometry>
        <box size="0.01 0.01 0.01"/>
      </geometry>
      <origin rpy="0 0 0" xyz="-0.01 0 0"/>
    </collision>
  </link>


  <!--################################################
  ########              arm 1                  #######
  ####################################################-->

  <link name="base_link_1">
    <visual>
      <geometry>
        <mesh filename="../ur5/meshes/visual/base.obj"/>
      </geometry>
      <material name="LightGrey">
        <color rgba="0.7 0.7 0.7 1.0"/>
      </material>
    </visual>
    <collision>
      <geometry>
        <mesh filename="../ur5/meshes/collision/base.stl"/>
      </geometry>
    </collision>
    <inertial>
      <mass value="4.0"/>
      <origin rpy="0 0 0" xyz="0.0 0.0 0.0"/>
      <inertia ixx="0.00443333156" ixy="0.0" ixz="0.0" iyy="0.00443333156" iyz="0.0" izz="0.0072"/>
    </inertial>
  </link>

  <joint name="shoulder_pan_joint_1" type="revolute">
    <parent link="base_link_1"/>
    <child link="shoulder_link_1"/>
    <origin rpy="0.0 0.0 0.0" xyz="0.0 0.0 0.089159"/>
    <axis xyz="0 0 1"/>
    <limit effort="150.0" lower="-3.14159265359" upper="3.14159265359" velocity="3.15"/>
    <dynamics damping="0.1" friction="0.0"/>
  </joint>
  <link name="shoulder_link_1">
    <visual>
      <geometry>
        <mesh filename="../ur5/meshes/visual/shoulder.obj"/>
      </geometry>
      <material name="UR-Blue">
        <color rgba="0.376 0.576 0.674 1.0"/>
      </material>
    </visual>
    <collision>
      <geometry>
        <mesh filename="../ur5/meshes/collision/shoulder.stl"/>
      </geometry>
    </collision>
    <inertial>
      <mass value="3.7"/>
      <origin rpy="0 0 0" xyz="0.0 0.0 0.0"/>
      <inertia ixx="0.010267495893" ixy="0.0" ixz="0.0" iyy="0.010267495893" iyz="0.0" izz="0.00666"/>
    </inertial>
  </link>
  <joint name="shoulder_lift_joint_1" type="revolute">
    <parent link="shoulder_link_1"/>
    <child link="upper_arm_link_1"/>
    <origin rpy="0.0 1.57079632679 0.0" xyz="0.0 0.13585 0.0"/>
    <axis xyz="0 1 0"/>
    <limit effort="150.0" lower="-3.14159265359" upper="3.14159265359" velocity="3.15"/>
    <dynamics damping="0.1" friction="0.0"/>
  </joint>
  <link name="upper_arm_link_1">
    <visual>
      <geometry>
        <mesh filename="../ur5/meshes/visual/upperarm.obj"/>
      </geometry>
      <material name="LightGrey">
        <color rgba="0.7 0.7 0.7 1.0"/>
      </material>
    </visual>
    <collision>
      <geometry>
        <mesh filename="../ur5/meshes/collision/upperarm.stl"/>
      </geometry>
    </collision>
    <inertial>
      <mass value="8.393"/>
      <origin rpy="0 0 0" xyz="0.0 0.0 0.28"/>
      <inertia ixx="0.22689067591" ixy="0.0" ixz="0.0" iyy="0.22689067591" iyz="0.0" izz="0.0151074"/>
    </inertial>
  </link>
  <joint name="elbow_joint_1" type="revolute">
    <parent link="upper_arm_link_1"/>
    <child link="forearm_link_1"/>
    <origin rpy="0.0 0.0 0.0" xyz="0.0 -0.1197 0.425"/>
    <axis xyz="0 1 0"/>
    <limit effort="150.0" lower="-3.14159265359" upper="3.14159265359" velocity="3.15"/>
    <dynamics damping="0.1" friction="0.0"/>
  </joint>
  <link name="forearm_link_1">
    <visual>
      <geometry>
        <mesh filename="../ur5/meshes/visual/forearm.obj"/>
      </geometry>
      <material name="LightGrey">
        <color rgba="0.7 0.7 0.7 1.0"/>
      </material>
    </visual>
    <collision>
      <geometry>
        <mesh filename="../ur5/meshes/collision/forearm.stl"/>
      </geometry>
    </collision>
    <inertial>
      <mass value="2.275"/>
      <origin rpy="0 0 0" xyz="0.0 0.0 0.25"/>
      <inertia ixx="0.049443313556" ixy="0.0" ixz="0.0" iyy="0.049443313556" iyz="0.0" izz="0.004095"/>
    </inertial>
  </link>
  <joint name="wrist_1_joint_1" type="revolute">
    <parent link="forearm_link_1"/>
    <child link="wrist_1_link_1"/>
    <origin rpy="0.0 1.57079632679 0.0" xyz="0.0 0.0 0.39225"/>
    <axis xyz="0 1 0"/>
    <limit effort="28.0" lower="-3.14159265359" upper="3.14159265359" velocity="3.2"/>
    <dynamics damping="0.1" friction="0.0"/>
  </joint>
  <link name="wrist_1_link_1">
    <visual>
      <geometry>
        <mesh filename="../ur5/meshes/visual/wrist1.obj"/>
      </geometry>
      <material name="UR-Blue">
        <color rgba="0.376 0.576 0.674 1.0"/>
      </material>
    </visual>
    <collision>
      <geometry>
        <mesh filename="../ur5/meshes/collision/wrist1.stl"/>
      </geometry>
    </collision>
    <inertial>
      <mass value="1.219"/>
      <origin rpy="0 0 0" xyz="0.0 0.0 0.0"/>
      <inertia ixx="0.111172755531" ixy="0.0" ixz="0.0" iyy="0.111172755531" iyz="0.0" izz="0.21942"/>
    </inertial>
  </link>
  <joint name="wrist_2_joint_1" type="revolute">
    <parent link="wrist_1_link_1"/>
    <child link="wrist_2_link_1"/>
    <origin rpy="0.0 0.0 0.0" xyz="0.0 0.093 0.0"/>
    <axis xyz="0 0 1"/>
    <limit effort="28.0" lower="-3.14159265359" upper="3.14159265359" velocity="3.2"/>
    <dynamics damping="0.1" friction="0.0"/>
  </joint>
  <link name="wrist_2_link_1">
    <visual>
      <geometry>
        <mesh filename="../ur5/meshes/visual/wrist2.obj"/>
      </geometry>
      <material name="DarkGray">
        <color rgba="0.5 0.5 0.5 1.0"/>
      </material>
    </visual>
    <collision>
      <geometry>
        <mesh filename="../ur5/meshes/collision/wrist2.stl"/>
      </geometry>
    </collision>
    <inertial>
      <mass value="1.219"/>
      <origin rpy="0 0 0" xyz="0.0 0.0 0.0"/>
      <inertia ixx="0.111172755531" ixy="0.0" ixz="0.0" iyy="0.111172755531" iyz="0.0" izz="0.21942"/>
    </inertial>
  </link>
  <joint name="wrist_3_joint_1" type="revolute">
    <parent link="wrist_2_link_1"/>
    <child link="wrist_3_link_1"/>
    <origin rpy="0.0 0.0 0.0" xyz="0.0 0.0 0.09465"/>
    <axis xyz="0 1 0"/>
    <limit effort="28.0" lower="-3.14159265359" upper="3.14159265359" velocity="3.2"/>
    <dynamics damping="0.1" friction="0.0"/>
  </joint>
  <link name="wrist_3_link_1">
    <visual>
      <geometry>
        <mesh filename="../ur5/meshes/visual/wrist3.obj"/>
      </geometry>
      <material name="LightGrey">
        <color rgba="0.7 0.7 0.7 1.0"/>
      </material>
    </visual>
    <collision>
      <geometry>
        <mesh filename="../ur5/meshes/collision/wrist3.stl"/>
      </geometry>
    </collision>
    <inertial>
      <mass value="0.1879"/>
      <origin rpy="0 0 0" xyz="0.0 0.0 0.0"/>
      <inertia ixx="0.0171364731454" ixy="0.0" ixz="0.0" iyy="0.0171364731454" iyz="0.0" izz="0.033822"/>
    </inertial>
  </link>
  <joint name="ee_fixed_joint_1" type="fixed">
    <parent link="wrist_3_link_1"/>
    <child link="ee_link_1"/>
    <origin rpy="0.0 0.0 1.57079632679" xyz="0.0 0.0823 0.0"/>
    <dynamics damping="0.1" friction="0.0"/>
  </joint>
  <link name="ee_link_1">
    <collision>
      <geometry>
        <box size="0.01 0.01 0.01"/>
      </geometry>
      <origin rpy="0 0 0" xyz="-0.01 0 0"/>
    </collision>
  </link>

  <!--################################################
  ########         shared base joints          #######
  ####################################################-->

  <joint name="base_link_joint_0" type="fixed">
    <parent link="base_fixture_link"/>
    <child link="base_link_0"/>
    <origin rpy="0 0 0" xyz="0.3 0.75 0"/>
  </joint>


  <!-- joints: main serial chain -->
  <joint name="base_link_joint_1" type="fixed">
    <parent link="base_fixture_link"/>
    <child link="base_link_1"/>
    <origin rpy="0 0 0.0" xyz="-0.3 0.75 0"/>
  </joint>

</robot>
